<?xml version="1.0" encoding="UTF-8"?>
<testng-results skipped="0" failed="2" ignored="0" total="5" passed="3">
  <reporter-output>
  </reporter-output>
  <suite name="Automation Reporto" duration-ms="110" started-at="2019-09-01T17:25:13 IST" finished-at="2019-09-01T17:25:13 IST">
    <groups>
    </groups>
    <test name="testTest" duration-ms="110" started-at="2019-09-01T17:25:13 IST" finished-at="2019-09-01T17:25:13 IST">
      <class name="com.test.sample.FunctionalSample1">
        <test-method status="PASS" signature="TestA()[pri:0, instance:com.test.sample.FunctionalSample1@531be3c5]" name="TestA" duration-ms="10" started-at="2019-09-01T17:25:13 IST" description="Launches the WordPress site" finished-at="2019-09-01T17:25:13 IST">
          <reporter-output>
          </reporter-output>
        </test-method> <!-- TestA -->
        <test-method status="FAIL" signature="TestB()[pri:0, instance:com.test.sample.FunctionalSample1@531be3c5]" name="TestB" duration-ms="7" started-at="2019-09-01T17:25:13 IST" finished-at="2019-09-01T17:25:13 IST">
          <exception class="java.lang.AssertionError">
            <message>
              <![CDATA[expected 3 but got 4 expected [4] but found [2]]]>
            </message>
            <full-stacktrace>
              <![CDATA[java.lang.AssertionError: expected 3 but got 4 expected [4] but found [2]
at org.testng.Assert.fail(Assert.java:97)
at org.testng.Assert.assertEqualsImpl(Assert.java:136)
at org.testng.Assert.assertEquals(Assert.java:118)
at org.testng.Assert.assertEquals(Assert.java:575)
at com.test.sample.FunctionalSample1.TestB(FunctionalSample1.java:16)
at sun.reflect.NativeMethodAccessorImpl.invoke0(Native Method)
at sun.reflect.NativeMethodAccessorImpl.invoke(NativeMethodAccessorImpl.java:62)
at sun.reflect.DelegatingMethodAccessorImpl.invoke(DelegatingMethodAccessorImpl.java:43)
at java.lang.reflect.Method.invoke(Method.java:498)
at org.testng.internal.MethodInvocationHelper.invokeMethod(MethodInvocationHelper.java:133)
at org.testng.internal.TestInvoker.invokeMethod(TestInvoker.java:584)
at org.testng.internal.TestInvoker.invokeTestMethod(TestInvoker.java:172)
at org.testng.internal.MethodRunner.runInSequence(MethodRunner.java:46)
at org.testng.internal.TestInvoker$MethodInvocationAgent.invoke(TestInvoker.java:804)
at org.testng.internal.TestInvoker.invokeTestMethods(TestInvoker.java:145)
at org.testng.internal.TestMethodWorker.invokeTestMethods(TestMethodWorker.java:146)
at org.testng.internal.TestMethodWorker.run(TestMethodWorker.java:128)
at java.util.concurrent.ThreadPoolExecutor.runWorker(ThreadPoolExecutor.java:1149)
at java.util.concurrent.ThreadPoolExecutor$Worker.run(ThreadPoolExecutor.java:624)
at java.lang.Thread.run(Thread.java:748)
]]>
            </full-stacktrace>
          </exception> <!-- java.lang.AssertionError -->
          <reporter-output>
          </reporter-output>
        </test-method> <!-- TestB -->
        <test-method status="PASS" signature="TestC()[pri:0, instance:com.test.sample.FunctionalSample1@531be3c5]" name="TestC" duration-ms="1" started-at="2019-09-01T17:25:13 IST" finished-at="2019-09-01T17:25:13 IST">
          <reporter-output>
          </reporter-output>
        </test-method> <!-- TestC -->
        <test-method status="FAIL" signature="TestD()[pri:0, instance:com.test.sample.FunctionalSample1@531be3c5]" name="TestD" duration-ms="1" started-at="2019-09-01T17:25:13 IST" finished-at="2019-09-01T17:25:13 IST">
          <exception class="java.lang.AssertionError">
            <message>
              <![CDATA[null]]>
            </message>
            <full-stacktrace>
              <![CDATA[java.lang.AssertionError: null
at org.testng.Assert.fail(Assert.java:97)
at org.testng.Assert.fail(Assert.java:102)
at com.test.sample.FunctionalSample1.TestD(FunctionalSample1.java:27)
at sun.reflect.NativeMethodAccessorImpl.invoke0(Native Method)
at sun.reflect.NativeMethodAccessorImpl.invoke(NativeMethodAccessorImpl.java:62)
at sun.reflect.DelegatingMethodAccessorImpl.invoke(DelegatingMethodAccessorImpl.java:43)
at java.lang.reflect.Method.invoke(Method.java:498)
at org.testng.internal.MethodInvocationHelper.invokeMethod(MethodInvocationHelper.java:133)
at org.testng.internal.TestInvoker.invokeMethod(TestInvoker.java:584)
at org.testng.internal.TestInvoker.invokeTestMethod(TestInvoker.java:172)
at org.testng.internal.MethodRunner.runInSequence(MethodRunner.java:46)
at org.testng.internal.TestInvoker$MethodInvocationAgent.invoke(TestInvoker.java:804)
at org.testng.internal.TestInvoker.invokeTestMethods(TestInvoker.java:145)
at org.testng.internal.TestMethodWorker.invokeTestMethods(TestMethodWorker.java:146)
at org.testng.internal.TestMethodWorker.run(TestMethodWorker.java:128)
at java.util.concurrent.ThreadPoolExecutor.runWorker(ThreadPoolExecutor.java:1149)
at java.util.concurrent.ThreadPoolExecutor$Worker.run(ThreadPoolExecutor.java:624)
at java.lang.Thread.run(Thread.java:748)
]]>
            </full-stacktrace>
          </exception> <!-- java.lang.AssertionError -->
          <reporter-output>
          </reporter-output>
        </test-method> <!-- TestD -->
        <test-method status="PASS" signature="TestE()[pri:0, instance:com.test.sample.FunctionalSample1@531be3c5]" name="TestE" duration-ms="0" started-at="2019-09-01T17:25:13 IST" finished-at="2019-09-01T17:25:13 IST">
          <reporter-output>
          </reporter-output>
        </test-method> <!-- TestE -->
      </class> <!-- com.test.sample.FunctionalSample1 -->
    </test> <!-- testTest -->
  </suite> <!-- Automation Reporto -->
</testng-results>
